Workbook

Sheet 入力_出力
A1: Original: https://docs.google.com/spreadsheets/d/168yQqMraFk7bT6RY7EYIYnq3xiPL9NeDUHJOtSBOmFs . I translated a few things. If you have any feedback, contact communistmountain on Discord
A2: Differences: skill activation, "rushing", downhill options (downhill WIP). Considers Pace Down and Speed Up modes. Fix: recovery levels have +0.02 per level not *1.02
A3: Latest update: 8/7/2025
A4: Make a copy, then edit the boxes with this background color.
C6: Uma's Status
C7: Speed | D7: Stamina | G7: Power | J7: Guts | M7: Wit
C8: 1088 | D8: 625 | G8: 621 | J8: 488 | M8: 435
C10: Track Aptitude | D10: Turf | E10: S | G10: Dirt | H10: B
C12: Distance Apt. | D12: Sprint | E12: A | G12: Mile | H12: A | J12: Medium | K12: D | M12: Long | N12: G
Q13: PLEASE MAKE A COPY! I WILL NOT SHARE ACCESS! THANK YOU <3
C14: Style Apt. | D14: Front | E14: B | G14: Pace | H14: A | J14: Late | K14: E | M14: End | N14: G
C16: Mood | D16: Awful | G16: Style | J16: Pace
C18: Assume "Rushing" never happens (0), always happens (1) or at the rate below (anything else) | J18: 1
C19: Original Calculator uses "never happens"
C23: Recovery Skills
C24: HP recovery | D24: Non-Uniques | H24: Unique Level (e.g. Urara; assume it reliably procs)
D25: Enter number of skills | H25: Enter level. +0.02 effect per level above 1, e.g. lvl 3, base 5.5%: 5.5% * 1.04 = 5.72%
C26: 0.015 | D26: 0 | H26: 0
C27: ↑ White Skills, Inherited Uniques (inherited is under non-unique col)
C28: 0.035 | D28: 0 | H28: 0 | K28: Check Stamina Recovery of skills at
C29: ↑ 1-star or 2-star Uniques | K29: https://gametora.com/umamusume/skills
C30: 0.055 | D30: 0 | H30: 0 | K30: Ensure server is set to Global
C31: ↑ Gold Skills and 3-star+ Uniques
C32: Custom | D32: 0 | H32: 0
C33: For skills in the future which give things like 0.35% or 7.5% Enter the exact % instead of number of skills or level of unique for this (note the Unique level formula).
C35: Consider Skill Proc Rate (1=Yes, 0=No) | H35: 1
C36: "No" lets you know the minimum Wit-reliant skills that need to proc to survive. Original Calculator uses "No".
C37: "Yes" means taking the average HP gain from Wit-reliant skills over multiple races.
C40: Race Information
C41: Surface | D41: Turf | G41: Condition | J41: Firm
C42: Distance | D42: 1600 | G42: Category | J42: =VLOOKUP(D42,'定義'!$O$3:$P$18,2) -> Mile
H45: Output!
C50: Uma's Actual Stats
C51: Speed | D51: Stamina | G51: Power | J51: Guts | M51: Wisdom
C52: {=(C8*VLOOKUP($D$16,'定義'!$B$23:$C$27,2, FALSE)+index('定義'!$K$13:$M$20,match($J$41,'定義'!$J$13:$J$16, 0)+if($D$41="Dirt",4,0),1))*VLOOKUP(switch($J$42,"Sprint",$E$12,"Mile",$H$12,"Medium",$K$12,"Long",$N$12),'定義'!$E$3:$G$10,2, FALSE)^2} -> 1044.48 | D52: =(D8*VLOOKUP($D$16,'定義'!$B$23:$C$27,2, FALSE)) -> 600 | G52: {=(G8*VLOOKUP($D$16,'定義'!$B$23:$C$27,2, FALSE)+index('定義'!$K$13:$M$20,match($J$41,'定義'!$J$13:$J$16, 0)+if($D$41="Dirt",4,0),2))*VLOOKUP(switch($J$42,"Sprint",$E$12,"Mile",$H$12,"Medium",$K$12,"Long",$N$12),'定義'!$E$3:$G$10,3, FALSE)^2*VLOOKUP(switch($D$41,"Turf",$E$10,"Dirt",$H$10),'定義'!$B$3:$C$10,2, FALSE)^2} -> 657.2664 | J52: =(J8*VLOOKUP($D$16,'定義'!$B$23:$C$27,2, FALSE)) -> 468.48 | M52: =(M8*VLOOKUP($D$16,'定義'!$B$23:$C$27,2, FALSE))*VLOOKUP(switch($J$16,"Front",$E$14,"Pace",$H$14,"Late",$K$14,"End",$N$14),'定義'!$I$3:$J$10,2, FALSE) -> 417.6
C54: Last Spurt 完走する為に→ | D54: Stamina Needed | G54: =IF(D52+1<D55,"Not enough stamina/guts！",IF(and(D52/D55<1.1,D55>=0),"Borderline！","You have enough！")) -> Borderline！
D55: ='定義'!G57 -> 570.22039
C57: Skill Proc Rate | D57: =max(100-9000/M52,20)/100 -> 0.78448276 | G57: "Rushing" Rate | J57: =MIN((6.5/LOG10(0.1*M52+1))^2/100, 1) -> 0.15881763
C61: Other Data
C62: Initial HP | D62: ='定義'!B34 -> 2027.2 | G62: Displayed Time | J62: ='定義'!B30 -> 90.837056 | L62: [s]
...

Sheet 定義
A1: 定義
B2: Track Aptitude | C2: Coefficient | E2: Distance Aptitude | F2: Speed Correction | G2: Acceleration Correction | I2: Style Aptitude | J2: Coefficient | O2: Distance | P2: Aptitude Name | S2: Style | T2: HP Correction | U2: Speed Correction | X2: Acceleration Correction
B3: S | C3: 1.05 | E3: S | F3: 1.05 | G3: 1 | I3: S | J3: 1.1 | O3: 1000 | P3: Sprint | S3: Front | T3: 0.95 | U3: 1 | V3: 0.98 | W3: 0.962 | X3: 1 | Y3: 1 | Z3: 0.996
B4: A | C4: 1 | E4: A | F4: 1 | G4: 1 | I4: A | J4: 1 | O4: 1200 | P4: Sprint | S4: Pace | T4: 0.89 | U4: 0.978 | V4: 0.991 | W4: 0.975 | X4: 0.985 | Y4: 1 | Z4: 0.996
B5: B | C5: 0.9 | E5: B | F5: 0.9 | G5: 1 | I5: B | J5: 0.85 | O5: 1400 | P5: Sprint | S5: Late | T5: 1 | U5: 0.938 | V5: 0.998 | W5: 0.994 | X5: 0.975 | Y5: 1 | Z5: 1
B6: C | C6: 0.8 | E6: C | F6: 0.8 | G6: 1 | I6: C | J6: 0.75 | O6: 1500 | P6: Mile | S6: End | T6: 0.995 | U6: 0.931 | V6: 1 | W6: 1 | X6: 0.945 | Y6: 1 | Z6: 0.997
B7: D | C7: 0.7 | E7: D | F7: 0.6 | G7: 1 | I7: D | J7: 0.6 | O7: 1600 | P7: Mile
B8: E | C8: 0.5 | E8: E | F8: 0.4 | G8: 0.6 | I8: E | J8: 0.4 | O8: 1800 | P8: Mile
B9: F | C9: 0.3 | E9: F | F9: 0.2 | G9: 0.5 | I9: F | J9: 0.2 | O9: 2000 | P9: Medium | U9: =U3/6 -> 0.16666667 | V9: =V3 * (4/6) -> 0.65333333 | W9: =W3 * (2/6) -> 0.32066667 | X9: =sum(U9:W9) -> 1.1406667
B10: G | C10: 0.1 | E10: G | F10: 0.1 | G10: 0.4 | I10: G | J10: 0.1 | O10: 2200 | P10: Medium | U10: =U4/6 -> 0.163 | V10: =V4 * (4/6) -> 0.66066667 | W10: =W4 * (2/6) -> 0.325 | X10: =sum(U10:W10) -> 1.1486667
O11: 2300 | P11: Medium | U11: =U5/6 -> 0.15633333 | V11: =V5 * (4/6) -> 0.66533333 | W11: =W5 * (2/6) -> 0.33133333 | X11: =sum(U11:W11) -> 1.153
B12: Track | C12: Value | E12: Condition | F12: Value | I12: Track | J12: Condition | K12: 補正スピード | L12: 補正パワー | M12: HP消費係数 | O12: 2400 | P12: Medium | U12: =U6/6 -> 0.15516667 | V12: =V6 * (4/6) -> 0.66666667 | W12: =W6 * (2/6) -> 0.33333333 | X12: =sum(U12:W12) -> 1.1551667
B13: Turf | C13: 1 | E13: Firm | F13: 1 | I13: Turf | J13: Firm | K13: 0 | L13: 0 | M13: 1 | O13: 2500 | P13: Long
B14: Dirt | C14: 2 | E14: Good | F14: 2 | J14: Good | K14: 0 | L14: -50 | M14: 1 | O14: 2600 | P14: Long
E15: Soft | F15: 3 | J15: Soft | K15: 0 | L15: -50 | M15: 1.02 | O15: 3000 | P15: Long
E16: Heavy | F16: 4 | J16: Heavy | K16: -50 | L16: -50 | M16: 1.02 | O16: 3200 | P16: Long
I17: Dirt | J17: Firm | K17: 0 | L17: -100 | M17: 1 | O17: 3400 | P17: Long
J18: Good | K18: 0 | L18: -50 | M18: 1 | O18: 3600 | P18: Long
J19: Soft | K19: 0 | L19: -100 | M19: 1.01
J20: Heavy | K20: -50 | L20: -100 | M20: 1.02
B22: やる気 | C22: 補正
B23: Great | C23: 1.04
B24: Good | C24: 1.02
B25: Normal | C25: 1
B26: Bad | C26: 0.98
B27: Awful | C27: 0.96
A29: 計算
A30: 表示レース時間 | B30: =1.18 * B38 -> 90.837056 | C30: [s] | D30: （上限・下限による補正を受けない場合）
A31: ラストスパート距離 | B31: =min((B35 - sum(G41:G45) - ('入力_出力'!D42 / 3 - 60) * 20 * B36 * B37 * (B47 - B33 + 12) ^ 2 / 144 / B47) / (20 * B36 * B37 * ((B49 - B33 + 12) ^ 2 / 144 / B49 - (B47 - B33 + 12) ^ 2 / 144 / B47)) + 60,'入力_出力'!D42 / 3) -> 533.33333 | C31: [m]
A33: ベーススピード | B33: =20 - ('入力_出力'!$D$42 - 2000) / 1000 -> 20.4 | C33: [m/s] | E33: 補正後パラメータ | I33: 回復スキルHP | K33: =10000*('入力_出力'!C26*'入力_出力'!D26+'入力_出力'!C28*'入力_出力'!D28+'入力_出力'!C30*'入力_出力'!D30+'入力_出力'!D32)*('入力_出力'!D57^'入力_出力'!H35) -> 0 | L33: <- change from Original: skill proc rate taken into account. Recovery values not hardcoded.
A34: 初期HP | B34: ='入力_出力'!$D$42 + 0.8 * F35 * vlookup('入力_出力'!$J$16,$S$3:$Z$6, 2, FALSE) -> 2027.2 | E34: スピード値 | F34: {='入力_出力'!$C$8 * VLOOKUP('入力_出力'!$D$16,'定義'!$B$23:$C$27,2, FALSE)+index('定義'!$K$13:$M$20,match('入力_出力'!$J$41,'定義'!$J$13:$J$16, 0)+if('入力_出力'!$D$41="Dirt",4,0),1)} -> 1044.48 | I34: 固有回復スキルHP | K34: =10000*('入力_出力'!C26*IF('入力_出力'!H26=0,0,1+0.02*('入力_出力'!H26-1))+'入力_出力'!C28*IF('入力_出力'!H28=0,0,1+0.02*('入力_出力'!H28-1))+'入力_出力'!C30*IF('入力_出力'!H30=0,0,1+0.02*('入力_出力'!H30-1))+'入力_出力'!H32) -> 0 | L34: <- change from Original: Recovery values not hardcoded.
A35: 回復スキル込HP | B35: =B34 * (1 + (K33+K34) / 10000) -> 2027.2 | E35: Stamina value | F35: ='入力_出力'!$D$8 * VLOOKUP('入力_出力'!$D$16,'定義'!$B$23:$C$27,2, FALSE) -> 600
A36: Battlefield HP consumption coefficient | B36: {=index('定義'!$K$13:$M$20,match('入力_出力'!$J$41,'定義'!$J$13:$J$16, 0)+if('入力_出力'!$D$41="Dirt",4,0),3)} -> 1 | E36: パワー値 | F36: {='入力_出力'!$G$8 * VLOOKUP('入力_出力'!$D$16,'定義'!$B$23:$C$27,2, FALSE)+index('定義'!$K$13:$M$20,match('入力_出力'!$J$41,'定義'!$J$13:$J$16, 0)+if('入力_出力'!$D$41="Dirt",4,0),2)} -> 596.16
A37: 終盤HP消費係数 | B37: =1 + (200 / sqrt(600 * F37)) -> 1.3772323 | E37: 根性値 | F37: ='入力_出力'!$J$8 * VLOOKUP('入力_出力'!$D$16,'定義'!$B$23:$C$27,2, FALSE) -> 468.48
A38: 生レース時間 | B38: =sum(E41:E50) -> 76.980556 | C38: [s] | E38: 賢さ値 | F38: ='入力_出力'!$M$8 * VLOOKUP('入力_出力'!$D$16,'定義'!$B$23:$C$27,2, FALSE)*VLOOKUP(switch('入力_出力'!$J$16,"Front",'入力_出力'!$E$14,"Pace",'入力_出力'!$H$14,"Late",'入力_出力'!$K$14,"End",'入力_出力'!$N$14),'定義'!$I$3:$J$10,2, FALSE) -> 417.6
B40: 開始秒速 [m/s] | C40: 目標秒速 [m/s] | D40: 加速度 [m/s^2] | E40: 時間 [s] | F40: 距離 [m] | G40: HP消費量 | I40: Mid-leg top speed before Modes | L40: =(B33 * vlookup('入力_出力'!$J$16,$S$3:$Z$6, 4, FALSE) + ((F38 / 5500) * log10(F38 * 0.1) - 0.65 / 2) * 0.01 * B33) -> 20.175204
A41: スタートダッシュ | B41: 3 | C41: =B33 * 0.85 -> 17.34 | D41: =24 + 0.0006 * sqrt(500 * F36) * vlookup('入力_出力'!$J$16,$S$3:$Z$6, 6, FALSE) * VLOOKUP(switch('入力_出力'!$J$42,"Sprint",'入力_出力'!$E$12,"Mile",'入力_出力'!$H$12,"Medium",'入力_出力'!$K$12,"Long",'入力_出力'!$N$12),'定義'!$E$3:$G$10,3, FALSE) * VLOOKUP(switch('入力_出力'!$D$41,"Turf",'入力_出力'!$E$10,"Dirt",'入力_出力'!$H$10),'定義'!$B$3:$C$10,2, FALSE) -> 24.3388 | E41: =(C41 - B41) / D41 -> 0.58918271 | F41: =(B41 + C41) / 2 * E41 -> 5.9919881 | G41: =20 * B36 * E41 -> 11.783654 | I41: Non-normal Mode Uptime | L41: =('入力_出力'!D42/24/L40)/('入力_出力'!D42/24/L40+3) -> 0.52414083 | M41: <- Rough estimate of the uptime of non-normal modes like Speed Up and Pace Down. They stop even if Exit conditions are not met after running 1 section (1/24 of total distance), then there's a 3s cooldown before the next possible mode
A42: phase = 0 / 加速 | B42: =B33 * 0.85 -> 17.34 | C42: =B43 -> 19.910004 | D42: =0.0006 * sqrt(500 * F36) * vlookup('入力_出力'!$J$16,$S$3:$Z$6, 6, FALSE) * VLOOKUP(switch('入力_出力'!$J$42,"Sprint",'入力_出力'!$E$12,"Mile",'入力_出力'!$H$12,"Medium",'入力_出力'!$K$12,"Long",'入力_出力'!$N$12),'定義'!$E$3:$G$10,3, FALSE) * VLOOKUP(switch('入力_出力'!$D$41,"Turf",'入力_出力'!$E$10,"Dirt",'入力_出力'!$H$10),'定義'!$B$3:$C$10,2, FALSE) -> 0.33879984 | E42: =min((C42 - B42) / D42, (-B42 + sqrt(B42 ^ 2 + 2 * D42 * ('入力_出力'!D42 / 6 - F41))) / D42) -> 7.5856122 | F42: =(B42 + D42 * E42 / 2) * E42 -> 141.28204 | G42: =20 * B36 * ((D42 * E42 + B42 - B33 + 12) ^ 3 - (B42 - B33 + 12) ^ 3) / (3 * D42) / 144 -> 110.73 | I42: Pace Down Chance Assumption | L42: 0.05
A43: phase = 0 / 定常 | B43: =B33 * vlookup('入力_出力'!$J$16,$S$3:$Z$6, 3, FALSE) + ((F38 / 5500) * log10(F38 * 0.1) - 0.65 / 2) * 0.01 * B33 -> 19.910004 | D43: - | E43: =F43 / B43 -> 5.9966152 | F43: =max('入力_出力'!D42 / 6 - (F41 + F42), 0) -> 119.39263 | G43: =20 * B36 * (B43 - B33 + 12) ^ 2 / 144 * E43 -> 110.33788
A44: phase = 1 / 加減速 | B44: =B42 + D42 * E42 -> 19.910004 | C44: =B45 -> 20.146124 | D44: =if(B44 <= C44, 0.0006 * sqrt(500 * F36) * vlookup('入力_出力'!$J$16,$S$3:$Z$6, 7, FALSE) * VLOOKUP(switch('入力_出力'!$J$42,"Sprint",'入力_出力'!$E$12,"Mile",'入力_出力'!$H$12,"Medium",'入力_出力'!$K$12,"Long",'入力_出力'!$N$12),'定義'!$E$3:$G$10,3, FALSE) * VLOOKUP(switch('入力_出力'!$D$41,"Turf",'入力_出力'!$E$10,"Dirt",'入力_出力'!$H$10),'定義'!$B$3:$C$10,2, FALSE), -0.8) -> 0.34395923 | E44: =(C44 - B44) / D44 -> 0.68647589 | F44: =(B44 + C44) / 2 * E44 -> 13.748783 | G44: =20 * B36 * ((C44 - B33 + 12) ^ 3 - (B44 - B33 + 12) ^ 3) / (3 * D44) / 144 -> 12.892067
...
