Workbook
Name Green: Green!$A$2:$A$75

Sheet README
B2: UMAMUSUME RATING CALCULATOR
B6: INSTRUCTIONS 1. Make a copy of this file (File -> Make a Copy) PLEAaSE Do not download this sheet and use it in Excel, the calc WILL break 2. Read the instructions page here Umamusume Rating Calculator Eng. 3. Head over to the Main sheet and input stats, aptitudes and skills in the blue colored boxes. 4. Enjoy your cal-cu-la-tor. NOTE You may check a skill's score by checking out the different hidden sheets (View > Hidden Sheets) Quick link for copies to access original: Umamusume Rating Calculator Eng. There’s a Script in my calculator!! Scriptless copy of Rating calculator This sheet is more or less a translation of ウマ娘 評価シミュレーター, the original Japanese rating calculator. | J6: if any errors/discrepancies, suggestions or you require help please contact me on discord, x or Reddit @zdkr_4ii or u/zDakraii
B23: Data, Formulas and Idea: Umsatei Data: Umamusu Wiki & GameWith Media: Cygames, Inc. Inspiration: Maygi's calculators I do not own any media used

Sheet Main
B5: Speed | C5: Stamina | D5: Power | E5: Guts | F5: Wit | H5: Yellow | I5: Late Surger Straightaways ○ | K5: =IFERROR(VLOOKUP(I5, INDIRECT("'" & H5 & "'!A:B"), 2, FALSE), 0) -> 239
A6: Stat points | B6: 1200 | C6: 700 | D6: 800 | E6: 422 | F6: 596 | H6: Gold | I6: No Stopping Me! | K6: =IFERROR(VLOOKUP(I6, INDIRECT("'" & H6 & "'!A:B"), 2, FALSE), 0) -> 394
A7: Score | B7: {=FLOOR(LET( x,B6, block_size,50, multipliers,{0.5, 0.8, 1, 1.3, 1.6, 1.8, 2.1, 2.4, 2.6, 2.8, 2.9, 3, 3.1, 3.3, 3.4, 3.5, 3.9, 4.1, 4.2, 4.3, 5.2, 5.5, 6.6, 6.8, 6.9}, blocks,FLOOR(x/block_size,1), block_sum,SUM(IF(SEQUENCE(1,COLUMNS(multipliers))>blocks,0,multipliers*50)), remainder,MOD(x,block_size), remainder_sum,INDEX(multipliers,1,blocks+1)*(remainder+1), IFS(OR(x<0),0,OR(x<1201),block_sum+remainder_sum,OR(x>1200),3841) ),1)} -> 3841 | C7: {=FLOOR(LET( x,C6, block_size,50, multipliers,{0.5, 0.8, 1, 1.3, 1.6, 1.8, 2.1, 2.4, 2.6, 2.8, 2.9, 3, 3.1, 3.3, 3.4, 3.5, 3.9, 4.1, 4.2, 4.3, 5.2, 5.5, 6.6, 6.8, 6.9}, blocks,FLOOR(x/block_size,1), block_sum,SUM(IF(SEQUENCE(1,COLUMNS(multipliers))>blocks,0,multipliers*50)), remainder,MOD(x,block_size), remainder_sum,INDEX(multipliers,1,blocks+1)*(remainder+1), IFS(OR(x<0),0,OR(x<1201),block_sum+remainder_sum,OR(x>1200),3841) ),1)} -> 1463 | D7: {=FLOOR(LET( x,D6, block_size,50, multipliers,{0.5, 0.8, 1, 1.3, 1.6, 1.8, 2.1, 2.4, 2.6, 2.8, 2.9, 3, 3.1, 3.3, 3.4, 3.5, 3.9, 4.1, 4.2, 4.3, 5.2, 5.5, 6.6, 6.8, 6.9}, blocks,FLOOR(x/block_size,1), block_sum,SUM(IF(SEQUENCE(1,COLUMNS(multipliers))>blocks,0,multipliers*50)), remainder,MOD(x,block_size), remainder_sum,INDEX(multipliers,1,blocks+1)*(remainder+1), IFS(OR(x<0),0,OR(x<1201),block_sum+remainder_sum,OR(x>1200),3841) ),1)} -> 1808 | E7: {=FLOOR(LET( x,E6, block_size,50, multipliers,{0.5, 0.8, 1, 1.3, 1.6, 1.8, 2.1, 2.4, 2.6, 2.8, 2.9, 3, 3.1, 3.3, 3.4, 3.5, 3.9, 4.1, 4.2, 4.3, 5.2, 5.5, 6.6, 6.8, 6.9}, blocks,FLOOR(x/block_size,1), block_sum,SUM(IF(SEQUENCE(1,COLUMNS(multipliers))>blocks,0,multipliers*50)), remainder,MOD(x,block_size), remainder_sum,INDEX(multipliers,1,blocks+1)*(remainder+1), IFS(OR(x<0),0,OR(x<1201),block_sum+remainder_sum,OR(x>1200),3841) ),1)} -> 634 | F7: {=FLOOR(LET( x,F6, block_size,50, multipliers,{0.5, 0.8, 1, 1.3, 1.6, 1.8, 2.1, 2.4, 2.6, 2.8, 2.9, 3, 3.1, 3.3, 3.4, 3.5, 3.9, 4.1, 4.2, 4.3, 5.2, 5.5, 6.6, 6.8, 6.9}, blocks,FLOOR(x/block_size,1), block_sum,SUM(IF(SEQUENCE(1,COLUMNS(multipliers))>blocks,0,multipliers*50)), remainder,MOD(x,block_size), remainder_sum,INDEX(multipliers,1,blocks+1)*(remainder+1), IFS(OR(x<0),0,OR(x<1201),block_sum+remainder_sum,OR(x>1200),3841) ),1)} -> 1131 | H7: Green | I7: Standard Distance ○ | K7: =IFERROR(VLOOKUP(I7, INDIRECT("'" & H7 & "'!A:B"), 2, FALSE), 0) -> 129
H8: Gold | I8: Rising Dragon | K8: =IFERROR(VLOOKUP(I8, INDIRECT("'" & H8 & "'!A:B"), 2, FALSE), 0) -> 559
K9: =IFERROR(VLOOKUP(I9, INDIRECT("'" & H9 & "'!A:B"), 2, FALSE), 0) -> 0
K10: =IFERROR(VLOOKUP(I10, INDIRECT("'" & H10 & "'!A:B"), 2, FALSE), 0) -> 0
B11: Turf | C11: S-A | D11: Dirt | E11: G | F11: Aptitude Templates | K11: =IFERROR(VLOOKUP(I11, INDIRECT("'" & H11 & "'!A:B"), 2, FALSE), 0) -> 0
B12: Sprint | C12: Mile | D12: Medium | E12: Long | F12: Kawakami Princess | K12: =IFERROR(VLOOKUP(I12, INDIRECT("'" & H12 & "'!A:B"), 2, FALSE), 0) -> 0
B13: D-E-F | C13: B-C | D13: S-A | E13: D-E-F | K13: =IFERROR(VLOOKUP(I13, INDIRECT("'" & H13 & "'!A:B"), 2, FALSE), 0) -> 0
B14: Front | C14: Pace | D14: Late | E14: End | K14: =IFERROR(VLOOKUP(I14, INDIRECT("'" & H14 & "'!A:B"), 2, FALSE), 0) -> 0
B15: G | C15: B-C | D15: S-A | E15: D-E-F | K15: =IFERROR(VLOOKUP(I15, INDIRECT("'" & H15 & "'!A:B"), 2, FALSE), 0) -> 0
K16: =IFERROR(VLOOKUP(I16, INDIRECT("'" & H16 & "'!A:B"), 2, FALSE), 0) -> 0
K17: =IFERROR(VLOOKUP(I17, INDIRECT("'" & H17 & "'!A:B"), 2, FALSE), 0) -> 0
K18: =IFERROR(VLOOKUP(I18, INDIRECT("'" & H18 & "'!A:B"), 2, FALSE), 0) -> 0
B19: Unique Skill Lvl | C19: 4 | E19: =IFS( C25 < 300, IMAGE("https://ucarecdn.com/5ebd9b54-6861-451f-81e4-d927c0f93871/G.png"), C25 < 600, IMAGE("https://ucarecdn.com/5a33b751-4fde-4d02-af73-08c6b7c2eb16/G.png"), C25 < 900, IMAGE("https://ucarecdn.com/d5314f9d-5258-4541-afcd-9a73180d26a8/F.png"), C25 < 1300, IMAGE("https://ucarecdn.com/7172c064-5696-4331-ab0c-d91fda76fff6/F.png"), C25 < 1800, IMAGE("https://ucarecdn.com/ff2aad3a-1a0e-4ee3-a139-df3bca013bb4/E.png"), C25 < 2300, IMAGE("https://ucarecdn.com/2d98094f-0980-4c86-84f7-12feff970e11/E.png"), C25 < 2900, IMAGE("https://ucarecdn.com/510464a1-4bbe-449f-9ef3-353df9fa9287/D.png"), C25 < 3500, IMAGE("https://ucarecdn.com/20806fc3-a266-4a24-85fc-83f2e72e3e6f/D.png"), C25 < 4900, IMAGE("https://ucarecdn.com/c24c1d96-c814-475e-b96c-e269b26dd4a3/C.png"), C25 < 6500, IMAGE("https://ucarecdn.com/ca5724b8-0274-431e-a0ea-72a809cc9051/C.png"), C25 < 8200, IMAGE("https://ucarecdn.com/77340b52-f3e0-4bbf-991e-cb6c093a47fe/B.png"), C25 < 10000, IMAGE("https://ucarecdn.com/74ae2bd7-df98-4c4b-9c0c-9a95e2a068a7/B.png"), C25 < 12100, IMAGE("https://ucarecdn.com/bc198b34-d0d5-4526-9f12-e4e20d2fd06c/A.png"), C25 < 14500, IMAGE("https://ucarecdn.com/d6e22ea0-5e90-4f9e-8e7f-0446b1cd8b35/A.png"), C25 < 15900, IMAGE("https://ucarecdn.com/fe47a6cf-39fd-4f43-bd65-8de0bcdd5125/S.png"), C25 < 17500, IMAGE("https://ucarecdn.com/1d62b8ec-99f0-46ee-ae08-0ea3e9d07fdd/S.png"), C25 < 19200, IMAGE("https://ucarecdn.com/902b5f72-f9e3-4727-b8a3-6a859e3c395c/SS.png"), C25 < 19600, IMAGE("https://ucarecdn.com/350624dc-889b-41d1-8dd5-ea23b66113a0/SS.png"), C25 < 20000, IMAGE("https://ucarecdn.com/6cf688d0-d852-418d-bb2d-5e695dd5a36e/UG.png"), C25 < 20400, IMAGE("https://ucarecdn.com/d60b208e-c6b8-4d0f-b6e6-9dc110ca4e0c/UG1.png"), C25 < 20800, IMAGE("https://ucarecdn.com/25ca9dc6-fa97-4440-842e-0715b066be42/UG2.png"), C25 < 21200, IMAGE("https://ucarecdn.com/ada20e59-4fd7-4468-a583-0985b3277629/UG3.png"), C25 < 21600, IMAGE("https://ucarecdn.com/c10300ca-84d4-4340-814e-89ad0feae078/UG4.png"), C25 < 22100, IMAGE("https://ucarecdn.com/d0970ada-c050-49a5-bbd4-80e62f825675/UG5.png"), C25 >= 22100, IMAGE("https://ucarecdn.com/532c5060-0a96-4652-ab4e-cb9d445d4d8f/UG6.png") ) | K19: =IFERROR(VLOOKUP(I19, INDIRECT("'" & H19 & "'!A:B"), 2, FALSE), 0) -> 0
B20: Uma Star Lvl | C20: 3★ | K20: =IFERROR(VLOOKUP(I20, INDIRECT("'" & H20 & "'!A:B"), 2, FALSE), 0) -> 0
B21: Score | C21: =IFS( OR(C20 = "1★", C20 = "2★"), C19*120, OR(C20 = "3★", C20 = "4★", C20 = "5★"), C19*170 ) -> 680 | K21: =IFERROR(VLOOKUP(I21, INDIRECT("'" & H21 & "'!A:B"), 2, FALSE), 0) -> 0
K22: =IFERROR(VLOOKUP(I22, INDIRECT("'" & H22 & "'!A:B"), 2, FALSE), 0) -> 0
K23: =IFERROR(VLOOKUP(I23, INDIRECT("'" & H23 & "'!A:B"), 2, FALSE), 0) -> 0
K24: =IFERROR(VLOOKUP(I24, INDIRECT("'" & H24 & "'!A:B"), 2, FALSE), 0) -> 0
B25: Total Score | C25: =SUM(B7:F7)+C21+SUM(K5:K46) -> 10878 | E25: =IFS( C25 < 300, "G Rank", C25 < 600, "G+ Rank", C25 < 900, "F Rank", C25 < 1300, "F+ Rank", C25 < 1800, "E Rank", C25 < 2300, "E+ Rank", C25 < 2900, "D Rank", C25 < 3500, "D+ Rank", C25 < 4900, "C Rank", C25 < 6500, "C+ Rank", C25 < 8200, "B Rank", C25 < 10000, "B+ Rank", C25 < 12100, "A Rank", C25 < 14500, "A+ Rank", C25 < 15900, "S Rank", C25 < 17500, "S+ Rank", C25 < 19200, "SS Rank", C25 < 19600, "SS+ Rank", C25 < 20000, "Ug⁰ Rank", C25 < 20400, "Ug¹ Rank", C25 < 20800, "Ug² Rank", C25 < 21200, "Ug³ Rank", C25 < 21600, "Ug⁴ Rank", C25 < 22100, "Ug⁵ Rank", C25 >= 22100, "Ug⁶ Rank" ) -> A Rank | K25: =IFERROR(VLOOKUP(I25, INDIRECT("'" & H25 & "'!A:B"), 2, FALSE), 0) -> 0
B26: Next Rank | C26: =IFS( C25 < 300, 300 - C25, C25 < 600, 600 - C25, C25 < 900, 900 - C25, C25 < 1300, 1300 - C25, C25 < 1800, 1800 - C25, C25 < 2300, 2300 - C25, C25 < 2900, 2900 - C25, C25 < 3500, 3500 - C25, C25 < 4900, 4900 - C25, C25 < 6500, 6500 - C25, C25 < 8200, 8200 - C25, C25 < 10000, 10000 - C25, C25 < 12100, 12100 - C25, C25 < 14500, 14500 - C25, C25 < 15900, 15900 - C25, C25 < 17500, 17500 - C25, C25 < 19600, 19600 - C25, C25 < 20000, 20000 - C25, C25 < 20400, 20400 - C25, C25 < 20800, 20800 - C25, C25 < 21200, 21200 - C25, C25 < 21600, 21600 - C25, C25 < 22100, 22100 - C25, C25 >= 22100, "Ug⁶ Rank" ) -> 1222 | K26: =IFERROR(VLOOKUP(I26, INDIRECT("'" & H26 & "'!A:B"), 2, FALSE), 0) -> 0
K27: =IFERROR(VLOOKUP(I27, INDIRECT("'" & H27 & "'!A:B"), 2, FALSE), 0) -> 0
B28: Sheet version: | C28: =IFERROR(__xludf.DUMMYFUNCTION("INDEX(FILTER(changelog!B:B , changelog!B:B<>""""), COUNTA(FILTER(changelog!B:B,changelog!B:B<>""""))) "),"2.2.5") -> 2.2.5 | K28: =IFERROR(VLOOKUP(I28, INDIRECT("'" & H28 & "'!A:B"), 2, FALSE), 0) -> 0
B29: Latest version: | C29: =IFERROR(__xludf.DUMMYFUNCTION("IMPORTRANGE(""https://docs.google.com/spreadsheets/d/1AAZCVDMiCozDNKte-5JYSm7SWUeVJ0o87i1iDY1bnWM/edit?gid=0#gid=0"", ""'changelog'!F1"")"),"2.2.5") -> 2.2.5 | K29: =IFERROR(VLOOKUP(I29, INDIRECT("'" & H29 & "'!A:B"), 2, FALSE), 0) -> 0
B30: Original Sheet: | C30: Umamusume Rating Calculator Eng. | K30: =IFERROR(VLOOKUP(I30, INDIRECT("'" & H30 & "'!A:B"), 2, FALSE), 0) -> 0
K31: =IFERROR(VLOOKUP(I31, INDIRECT("'" & H31 & "'!A:B"), 2, FALSE), 0) -> 0
K32: =IFERROR(VLOOKUP(I32, INDIRECT("'" & H32 & "'!A:B"), 2, FALSE), 0) -> 0
K33: =IFERROR(VLOOKUP(I33, INDIRECT("'" & H33 & "'!A:B"), 2, FALSE), 0) -> 0
K34: =IFERROR(VLOOKUP(I34, INDIRECT("'" & H34 & "'!A:B"), 2, FALSE), 0) -> 0
K35: =IFERROR(VLOOKUP(I35, INDIRECT("'" & H35 & "'!A:B"), 2, FALSE), 0) -> 0
K36: =IFERROR(VLOOKUP(I36, INDIRECT("'" & H36 & "'!A:B"), 2, FALSE), 0) -> 0
K37: =IFERROR(VLOOKUP(I37, INDIRECT("'" & H37 & "'!A:B"), 2, FALSE), 0) -> 0
K38: =IFERROR(VLOOKUP(I38, INDIRECT("'" & H38 & "'!A:B"), 2, FALSE), 0) -> 0
K39: =IFERROR(VLOOKUP(I39, INDIRECT("'" & H39 & "'!A:B"), 2, FALSE), 0) -> 0
K40: =IFERROR(VLOOKUP(I40, INDIRECT("'" & H40 & "'!A:B"), 2, FALSE), 0) -> 0
K41: =IFERROR(VLOOKUP(I41, INDIRECT("'" & H41 & "'!A:B"), 2, FALSE), 0) -> 0
K42: =IFERROR(VLOOKUP(I42, INDIRECT("'" & H42 & "'!A:B"), 2, FALSE), 0) -> 0
... K46: =IFERROR(VLOOKUP(I46, INDIRECT("'" & H46 & "'!A:B"), 2, FALSE), 0) -> 0
H47: FALSE | I47: Reset all

Sheet Instructions

Sheet Maths and Formulas
A41: Multipliers <=1200 | B41: [.5, .8, 1, 1.3, 1.6, 1.8, 2.1, 2.4, 2.6, 2.8, 2.9, 3, 3.1, 3.3, 3.4, 3.5, 3.9, 4.1, 4.2, 4.3, 5.2, 5.5, 6.6, 6.8, 6.9] | I41: https://pastebin.com/qSfsjwGC
A42: Multipliers >=1200 | B42: [7.888, 8, 8.1, 8.3, 8.4, 8.5, 8.6, 8.8, 8.9, 9, 9.2, 9.3, 9.4, 9.6, 9.7, 9.8, 10, 10.1, 10.2, 10.3, 10.5, 10.6, 10.7, 10.9, 11, 11.1, 11.3, 11.4, 11.5, 11.7, 11.8, 11.9, 12.1, 12.2, 12.3, 12.4, 12.6, 12.7, 12.8, 13, 13.1, 13.2, 13.4, 13.5, 13.6, 13.8, 13.9, 14, 14.1, 14.3, 14.4, 14.5, 14.7, 14.8, 14.9, 15.1, 15.2, 15.3, 15.5, 15.6, 15.7, 15.9, 16, 16.1, 16.2, 16.4, 16.5, 16.6, 16.8, 16.9, 17, 17.2, 17.3, 17.4, 17.6, 17.7, 17.8, 17.9, 18.1, 18.2, 18.3]

Sheet Validation
A2: {=TRANSPOSE(INDIRECT("'" & Main!H5 & "'!A1:A"))} -> None | B2: Ignited Spirit SPD | C2: Ignited Spirit PWR | D2: Ignited Spirit GUT | E2: Ignited Spirit WIT | F2: Corner Adept ○ | G2: Straightaway Adept | H2: Ramp Up | I2: Homestretch Haste | J2: Fast-Paced | K2: Prepared to Pass | L2: Position Pilfer | M2: Outer Swell | N2: Masterful Gambit | O2: Gap Closer | P2: Productive Plan | Q2: Up-Tempo | R2: Steadfast | S2: Inside Scoop | T2: Sprint Straightaways ◎ | U2: Sprint Straightaways ○ | V2: Sprint Corners ◎ | W2: Sprint Corners ○ | X2: Huge Lead | Y2: Mile Straightaways ◎ | Z2: Mile Straightaways ○ | AA2: Mile Corners ◎ | AB2: Mile Corners ○ | AC2: Shifting Gears | AD2: Unyielding Spirit | AE2: Medium Straightaways ◎ | AF2: Medium Straightaways ○ | AG2: Medium Corners ◎ | AH2: Medium Corners ○ | AI2: Long Straightaways ◎ | AJ2: Long Straightaways ○ | AK2: Long Corners ◎ | AL2: Long Corners ○ | AM2: Keeping the Lead | AN2: Pressure | AO2: Front Runner Straightaways ◎ | AP2: Front Runner Straightaways ○ | AQ2: Front Runner Corners ◎ | AR2: Front Runner Corners ○ | AS2: Leader's Pride | AT2: Pace Chaser Straightaways ◎ | AU2: Pace Chaser Straightaways ○ | AV2: Pace Chaser Corners ◎ | AW2: Pace Chaser Corners ○ | AX2: Late Surger Straightaways ◎ | AY2: Late Surger Straightaways ○ | AZ2: Later Surger Corners ◎ | BA2: Late Surger Corners ○ | BB2: 1,500,000 CC | BC2: End Closer Straightaways ◎ | BD2: End Closer Straightaways ○ | BE2: End Closer Corners ◎ | BF2: End Closer Corners ○ | BG2: Uma Stan | BH2: Tail Held High | BI2: Slipstream | BJ2: Playtime's Over! | BK2: Top Pick | BL2: Corner Acceleration ○ | BM2: Straightaway Acceleration | BN2: Nimble Navigator | BO2: Early Lead | BP2: Final Push | BQ2: Head-On | BR2: Slick Surge | BS2: Straightaway Spurt | BT2: Sprinting Gear | BU2: Updrafters | BV2: Countermeasure | BW2: Acceleration | BX2: Second Wind | BY2: Shrewd Step | BZ2: Straight Descent | CA2: Tactical Tweak | CB2: Fighter | CC2: Highlander | CD2: Groundwork | CE2: Prudent Positioning | CF2: Go with the Flow | CG2: Meticulous Measures | CH2: Thunderbolt Step | CI2: Dodging Danger | CJ2: Focus | CK2: Hawkeye | CL2: Studious | CM2: I Can See Right Through You | CN2: Strategist | CO2: All I've Got | CP2: Feature Act | CQ2: Early Start | CR2: Risky Business | CS2: Light as a Feather | CT2: Fighting Spirit | CU2: Eager | CV2: Pumped | CW2: Fearless | CX2: With All My Soul | CY2: Full Throttle | CZ2: Downhill Speedster | DA2: Take the Chance | DB2: Forward, March! | DC2: Glittering Star
A3: {=TRANSPOSE(INDIRECT("'" & Main!H6 & "'!A1:A"))} -> None | B3: Burning Spirit SPD | C3: Burning Spirit STA | D3: Burning Spirit PWR | E3: Burning Spirit GUT | F3: Burning Spirit WIT | G3: Runaway | H3: Super Lucky Seven | I3: Fall Frenzy | J3: Spring Spectacle | K3: Right-Handed Demon | L3: Yodo Invicta | M3: Firm Course Menace | N3: Swinging Maestro | O3: Breath of Fresh Air | P3: Iron Will | Q3: Indomitable | R3: Unruffled | S3: Calm and Collected | T3: Race Planner | U3: Sleeping Lion | V3: Keen Eye | W3: Trackblazer | X3: Cooldown | Y3: Adrenaline Rush | Z3: Miraculous Step | AA3: Restless | AB3: Gourmand | AC3: Relax | AD3: Go-Home Specialist | AE3: Serenity | AF3: Lie in Wait | AG3: VIP Pass | AH3: Of Calm Mind | AI3: Master of the Sands | AJ3: Professor of Curvature | AK3: Beeline Burst | AL3: It's On! | AM3: In Body and Mind | AN3: Escape Artist | AO3: Speed Star | AP3: Fast & Furious | AQ3: Rising Dragon | AR3: Sturm und Drang | AS3: Blinding Flash | AT3: Mile Maven | AU3: Killer Tunes | AV3: Unyielding | AW3: Innate Experience | AX3: Staggering Lead | AY3: Changing Gears | AZ3: Big-Sisterly | BA3: Vanguard Spirit | BB3: Overwhelming Pressure | BC3: 15,000,000 CC | BD3: Trending in the Charts! | BE3: Corner Connoisseur | BF3: Rushing Gale! | BG3: No Stopping Me! | BH3: Taking the Lead | BI3: Unrestrained | BJ3: On Your Left! | BK3: Encroaching Shadow | BL3: Turbo Sprint | BM3: Furious Feat | BN3: Plan X | BO3: Step on the Gas! | BP3: Technician | BQ3: Determined Descent | BR3: Shatterproof | BS3: Hard Worker | BT3: Center Stage | BU3: Lane Legerdemain | BV3: Perfect Prep! | BW3: Lightning Step | BX3: Sixth Sense | BY3: Concentration | BZ3: Clairvoyance | CA3: The Bigger Picture | CB3: The Coast Is Clear! | CC3: Crusader | CD3: Superstan | CE3: Come What May | CF3: Tail Nine | CG3: Headliner | CH3: Daring Strike | CI3: Nothing Ventured | CJ3: Flash Forward | CK3: In High Spirits | CL3: Blast Forward | CM3: Top Runner | CN3: Burning Soul | CO3: Elated | CP3: Full of Vigor | CQ3: Dauntless | CR3: Wild Wind | CS3: See Ya Later! | CT3: Keep Going! | CU3: Moonlit Flash | CV3: Refraction Arc | CW3: From the Brink | CX3: Neck and Neck | CY3: Lead the Charge! | CZ3: Radiant Star | DA3: Best in Japan | DB3: Tantalizing Trick | DC3: Dominator | DD3: Petrifying Gaze | DE3: Adored by All | DF3: Battle Formation | DG3: Mystifying Murmur | DH3: Stamina Siphon | DI3: All-Seeing Eyes | DJ3: Illusionist | DK3: Dazzling Disorientation
A4: {=TRANSPOSE(INDIRECT("'" & Main!H7 & "'!A1:A"))} -> None | B4: Right-Handed ◎ | C4: Right-Handed ○ | D4: Left-Handed ◎ | E4: Left-Handed ○ | F4: Spring Runner ◎ | G4: Spring Runner ○ | H4: Summer Runner ◎ | I4: Summer Runner ○ | J4: Fall Runner ◎ | K4: Fall Runner ○ | L4: Winter Runner ◎ | M4: Winter Runner ○ | N4: Outer Post Proficiency ◎ | O4: Outer Post Proficiency ○ | P4: Maverick ◎ | Q4: Maverick ○ | R4: Long Shot ◎ | S4: Long Shot ○ | T4: Sympathy | U4: Lone Wolf | V4: Tokyo Racecourse ◎ | W4: Tokyo Racecourse ○ | X4: Nakayama Racecourse ◎ | Y4: Nakayama Racecourse ○ | Z4: Hanshin Racecourse ◎ | AA4: Hanshin Racecourse ○ | AB4: Kyoto Racecourse ◎ | AC4: Kyoto Racecourse ○ | AD4: Chukyo Racecourse ◎ | AE4: Chukyo Racecourse ○ | AF4: Sapporo Racecourse ◎ | AG4: Sapporo Racecourse ○ | AH4: Hakodate Racecourse ◎ | AI4: Hakodate Racecourse ○ | AJ4: Fukushima Racecourse ◎ | AK4: Fukushima Racecourse ○ | AL4: Niigata Racecourse ◎ | AM4: Niigata Racecourse ○ | AN4: Kokura Racecourse ◎ | AO4: Kokura Racecourse ○ | AP4: Standard Distance ◎ | AQ4: Standard Distance ○ | AR4: Non-Standard Distance ◎ | AS4: Non-Standard Distance ○ | AT4: Oi Racecourse ◎ | AU4: Oi Racecourse ○ | AV4: Restraint | AW4: Firm Conditions ◎ | AX4: Firm Conditions ○ | AY4: Wet Conditions ◎ | AZ4: Wet Conditions ○ | BA4: Competitive Spirit ◎ | BB4: Competitive Spirit ○ | BC4: Sunny Days ◎ | BD4: Sunny Days ○ | BE4: Cloudy Days ◎ | BF4: Cloudy Days ○ | BG4: Rainy Days ◎ | BH4: Rainy Days ○ | BI4: Snowy Days ◎ | BJ4: Snowy Days ○ | BK4: Target in Sight ◎ | BL4: Target in Sight ○ | BM4: Inner Post Proficiency ◎ | BN4: Inner Post Proficiency ○ | BO4: Front Runner Savvy ◎ | BP4: Front Runner Savvy ○ | BQ4: Pace Chaser Savvy ◎ | BR4: Pace Chaser Savvy ○ | BS4: Late Surger Savvy ◎ | BT4: Late Surger Savvy ○ | BU4: End Closer Savvy ◎ | BV4: End Closer Savvy ○ | BW4: Lucky Seven
A5: {=TRANSPOSE(INDIRECT("'" & Main!H8 & "'!A1:A"))} -> None | B5: Burning Spirit SPD | C5: Burning Spirit STA | D5: Burning Spirit PWR | E5: Burning Spirit GUT | F5: Burning Spirit WIT | G5: Runaway | H5: Super Lucky Seven | I5: Fall Frenzy | J5: Spring Spectacle | K5: Right-Handed Demon | L5: Yodo Invicta | M5: Firm Course Menace | N5: Swinging Maestro | O5: Breath of Fresh Air | P5: Iron Will | Q5: Indomitable | R5: Unruffled | S5: Calm and Collected | T5: Race Planner | U5: Sleeping Lion | V5: Keen Eye | W5: Trackblazer | X5: Cooldown | Y5: Adrenaline Rush | Z5: Miraculous Step | AA5: Restless | AB5: Gourmand | AC5: Relax | AD5: Go-Home Specialist | AE5: Serenity | AF5: Lie in Wait | AG5: VIP Pass | AH5: Of Calm Mind | AI5: Master of the Sands | AJ5: Professor of Curvature | AK5: Beeline Burst | AL5: It's On! | AM5: In Body and Mind | AN5: Escape Artist | AO5: Speed Star | AP5: Fast & Furious | AQ5: Rising Dragon | AR5: Sturm und Drang | AS5: Blinding Flash | AT5: Mile Maven | AU5: Killer Tunes | AV5: Unyielding | AW5: Innate Experience | AX5: Staggering Lead | AY5: Changing Gears | AZ5: Big-Sisterly | BA5: Vanguard Spirit | BB5: Overwhelming Pressure | BC5: 15,000,000 CC | BD5: Trending in the Charts! | BE5: Corner Connoisseur | BF5: Rushing Gale! | BG5: No Stopping Me! | BH5: Taking the Lead | BI5: Unrestrained | BJ5: On Your Left! | BK5: Encroaching Shadow | BL5: Turbo Sprint | BM5: Furious Feat | BN5: Plan X | BO5: Step on the Gas! | BP5: Technician | BQ5: Determined Descent | BR5: Shatterproof | BS5: Hard Worker | BT5: Center Stage | BU5: Lane Legerdemain | BV5: Perfect Prep! | BW5: Lightning Step | BX5: Sixth Sense | BY5: Concentration | BZ5: Clairvoyance | CA5: The Bigger Picture | CB5: The Coast Is Clear! | CC5: Crusader | CD5: Superstan | CE5: Come What May | CF5: Tail Nine | CG5: Headliner | CH5: Daring Strike | CI5: Nothing Ventured | CJ5: Flash Forward | CK5: In High Spirits | CL5: Blast Forward | CM5: Top Runner | CN5: Burning Soul | CO5: Elated | CP5: Full of Vigor | CQ5: Dauntless | CR5: Wild Wind | CS5: See Ya Later! | CT5: Keep Going! | CU5: Moonlit Flash | CV5: Refraction Arc | CW5: From the Brink | CX5: Neck and Neck | CY5: Lead the Charge! | CZ5: Radiant Star | DA5: Best in Japan | DB5: Tantalizing Trick | DC5: Dominator | DD5: Petrifying Gaze | DE5: Adored by All | DF5: Battle Formation | DG5: Mystifying Murmur | DH5: Stamina Siphon | DI5: All-Seeing Eyes | DJ5: Illusionist | DK5: Dazzling Disorientation
A6: {=TRANSPOSE(INDIRECT("'" & Main!H9 & "'!A1:A"))} -> #REF!
A7: {=TRANSPOSE(INDIRECT("'" & Main!H10 & "'!A1:A"))} -> #REF!
A8: {=TRANSPOSE(INDIRECT("'" & Main!H11 & "'!A1:A"))} -> #REF!
A9: {=TRANSPOSE(INDIRECT("'" & Main!H12 & "'!A1:A"))} -> #REF!
A10: {=TRANSPOSE(INDIRECT("'" & Main!H13 & "'!A1:A"))} -> #REF!
A11: {=TRANSPOSE(INDIRECT("'" & Main!H14 & "'!A1:A"))} -> #REF!
A12: {=TRANSPOSE(INDIRECT("'" & Main!H15 & "'!A1:A"))} -> #REF!
A13: {=TRANSPOSE(INDIRECT("'" & Main!H16 & "'!A1:A"))} -> #REF!
A14: {=TRANSPOSE(INDIRECT("'" & Main!H17 & "'!A1:A"))} -> #REF!
A15: {=TRANSPOSE(INDIRECT("'" & Main!H18 & "'!A1:A"))} -> #REF!
A16: {=TRANSPOSE(INDIRECT("'" & Main!H19 & "'!A1:A"))} -> #REF!
A17: {=TRANSPOSE(INDIRECT("'" & Main!H20 & "'!A1:A"))} -> #REF!
... A43: {=TRANSPOSE(INDIRECT("'" & Main!H46 & "'!A1:A"))} -> #REF!

Sheet Gold
A1: None | B1: 0
A2: Burning Spirit SPD | B2: 633
A3: Burning Spirit STA | B3: 633 | H3: Unchanging | I3: =SWITCH(Main!$C$15, "S-A", J3, "B-C", K3, "D-E-F", L3, "G", M3, "Not Found")
A4: Burning Spirit PWR | B4: 633
A5: Burning Spirit GUT | B5: 633
A6: Burning Spirit WIT | B6: 633
A7: Runaway | B7: =SWITCH(Main!$B$15, "S-A", C7, "B-C", D7, "D-E-F", E7, "G", F7, "Not Found") -> 259 | C7: 407 | D7: 333 | E7: 296 | F7: 259 | G7: Front
A8: Super Lucky Seven | B8: 334
A9: Fall Frenzy | B9: 461
A10: Spring Spectacle | B10: 461
A11: Right-Handed Demon | B11: 461
A12: Yodo Invicta | B12: 461
A13: Firm Course Menace | B13: 461
A14: Swinging Maestro | B14: 508
A15: Breath of Fresh Air | B15: 508
A16: Iron Will | B16: 508 | H16: =SWITCH(Main!$E$13, "S-A", C25, "B-C", D25, "D-E-F", E25, "G", F25, "Not Found") -> 406 | I16: unconfirmed if scoring is fixed, but likely the case
A17: Indomitable | B17: 508
A18: Unruffled | B18: 508
A19: Calm and Collected | B19: =SWITCH(Main!$C$15, "S-A", C19, "B-C", D19, "D-E-F", E19, "G", F19, "Not Found") -> 457 | C19: 559 | D19: 457 | E19: 406 | F19: 356 | G19: Pace
A20: Race Planner | B20: =SWITCH(Main!$C$15, "S-A", C20, "B-C", D20, "D-E-F", E20, "G", F20, "Not Found") -> 457 | C20: 559 | D20: 457 | E20: 406 | F20: 356 | G20: Pace
A21: Sleeping Lion | B21: =SWITCH(Main!$E$15, "S-A", C21, "B-C", D21, "D-E-F", E21, "G", F21, "Not Found") -> 406 | C21: 559 | D21: 457 | E21: 406 | F21: 356 | G21: End
A22: Keen Eye | B22: =SWITCH(Main!$C$13, "S-A", C22, "B-C", D22, "D-E-F", E22, "G", F22, "Not Found") -> 457 | C22: 559 | D22: 457 | E22: 406 | F22: 356 | G22: Mile
A23: Trackblazer | B23: =SWITCH(Main!$D$13, "S-A", C23, "B-C", D23, "D-E-F", E23, "G", F23, "Not Found") -> 559 | C23: 559 | D23: 457 | E23: 406 | F23: 356 | G23: Medium
A24: Cooldown | B24: =SWITCH(Main!$E$13, "S-A", C24, "B-C", D24, "D-E-F", E24, "G", F24, "Not Found") -> 406 | C24: 559 | D24: 457 | E24: 406 | F24: 356 | G24: Long
A25: Adrenaline Rush | B25: =SWITCH(Main!$E$13, "S-A", C25, "B-C", D25, "D-E-F", E25, "G", F25, "Not Found") -> 406 | C25: 559 | D25: 457 | E25: 406 | F25: 356 | G25: Long
A26: Miraculous Step | B26: =SWITCH(Main!$D$13, "S-A", C26, "B-C", D26, "D-E-F", E26, "G", F26, "Not Found") -> 559 | C26: 559 | D26: 457 | E26: 406 | F26: 356 | G26: Medium
A27: Restless | B27: =SWITCH(Main!$B$15, "S-A", C27, "B-C", D27, "D-E-F", E27, "G", F27, "Not Found") -> 356 | C27: 559 | D27: 457 | E27: 406 | F27: 356 | G27: Front
A28: Gourmand | B28: =SWITCH(Main!$C$15, "S-A", C28, "B-C", D28, "D-E-F", E28, "G", F28, "Not Found") -> 457 | C28: 559 | D28: 457 | E28: 406 | F28: 356 | G28: Pace
A29: Relax | B29: =SWITCH(Main!$D$15, "S-A", C29, "B-C", D29, "D-E-F", E29, "G", F29, "Not Found") -> 559 | C29: 559 | D29: 457 | E29: 406 | F29: 356 | G29: Late
A30: Go-Home Specialist | B30: =SWITCH(Main!$E$15, "S-A", C30, "B-C", D30, "D-E-F", E30, "G", F30, "Not Found") -> 406 | C30: 559 | D30: 457 | E30: 406 | F30: 356 | G30: End
A31: Serenity | B31: =SWITCH(Main!$E$15, "S-A", C31, "B-C", D31, "D-E-F", E31, "G", F31, "Not Found") -> 406 | C31: 559 | D31: 457 | E31: 406 | F31: 356 | G31: End
A32: Lie in Wait | B32: =SWITCH(Main!D$15, "S-A", C32, "B-C", D32, "D-E-F", E32, "G", F32, "Not Found") -> 559 | C32: 559 | D32: 457 | E32: 406 | F32: 356 | G32: Late
A33: VIP Pass | B33: =SWITCH(Main!E$13, "S-A", C33, "B-C", D33, "D-E-F", E33, "G", F33, "Not Found") -> 406 | C33: 559 | D33: 457 | E33: 406 | F33: 356 | G33: Long
A34: Of Calm Mind | B34: =SWITCH(Main!E$13, "S-A", C34, "B-C", D34, "D-E-F", E34, "G", F34, "Not Found") -> 406 | C34: 559 | D34: 457 | E34: 406 | F34: 356 | G34: Long
A35: Master of the Sands | B35: 508 | G35: Dirt
A36: Professor of Curvature | B36: 508
A37: Beeline Burst | B37: 508
A38: It's On! | B38: 508
A39: In Body and Mind | B39: 508
A40: Escape Artist | B40: =SWITCH(Main!$B$15, "S-A", C40, "B-C", D40, "D-E-F", E40, "G", F40, "Not Found") -> 356 | C40: 559 | D40: 457 | E40: 406 | F40: 356 | G40: Front
...

Sheet Green
A1: None | B1: 0
A2: Right-Handed ◎ | B2: 174
A3: Right-Handed ○ | B3: 129
A4: Left-Handed ◎ | B4: 174
A5: Left-Handed ○ | B5: 129
A6: Spring Runner ◎ | B6: 174
A7: Spring Runner ○ | B7: 129
A8: Summer Runner ◎ | B8: 174
A9: Summer Runner ○ | B9: 129
A10: Fall Runner ◎ | B10: 174
A11: Fall Runner ○ | B11: 129
A12: Winter Runner ◎ | B12: 174
... A48: Restraint | B48: 217
A49: Firm Conditions ◎ | B49: 174 | H49: Unquenched Thirst
A50: Firm Conditions ○ | B50: 129
A51: Wet Conditions ◎ | B51: 174
A52: Wet Conditions ○ | B52: 129
A53: Competitive Spirit ◎ | B53: 174
A54: Competitive Spirit ○ | B54: 129
A55: Sunny Days ◎ | B55: 174
A56: Sunny Days ○ | B56: 129
A57: Cloudy Days ◎ | B57: 174
A58: Cloudy Days ○ | B58: 129
A59: Rainy Days ◎ | B59: 174
A60: Rainy Days ○ | B60: 129
A61: Snowy Days ◎ | B61: 174
... A66: Inner Post Proficiency ○ | B66: 129
A67: Front Runner Savvy ◎ | B67: =SWITCH(Main!$B$15, "S-A", C67, "B-C", D67, "D-E-F", E67, "G", F67, "Not Found") -> 152 | C67: 239 | D67: 195 | E67: 174 | F67: 152 | G67: Front
A68: Front Runner Savvy ○ | B68: =SWITCH(Main!$B$15, "S-A", C68, "B-C", D68, "D-E-F", E68, "G", F68, "Not Found") -> 122 | C68: 191 | D68: 157 | E68: 139 | F68: 122 | G68: Front
A69: Pace Chaser Savvy ◎ | B69: =SWITCH(Main!$C$15, "S-A", C69, "B-C", D69, "D-E-F", E69, "G", F69, "Not Found") -> 195 | C69: 239 | D69: 195 | E69: 174 | F69: 152 | G69: Pace
A70: Pace Chaser Savvy ○ | B70: =SWITCH(Main!$C$15, "S-A", C70, "B-C", D70, "D-E-F", E70, "G", F70, "Not Found") -> 157 | C70: 191 | D70: 157 | E70: 139 | F70: 122 | G70: Pace
A71: Late Surger Savvy ◎ | B71: =SWITCH(Main!$D$15, "S-A", C71, "B-C", D71, "D-E-F", E71, "G", F71, "Not Found") -> 239 | C71: 239 | D71: 195 | E71: 174 | F71: 152 | G71: Late
A72: Late Surger Savvy ○ | B72: =SWITCH(Main!$D$15, "S-A", C72, "B-C", D72, "D-E-F", E72, "G", F72, "Not Found") -> 191 | C72: 191 | D72: 157 | E72: 139 | F72: 122 | G72: Late
A73: End Closer Savvy ◎ | B73: =SWITCH(Main!$E$15, "S-A", C73, "B-C", D73, "D-E-F", E73, "G", F73, "Not Found") -> 174 | C73: 239 | D73: 195 | E73: 174 | F73: 152 | G73: End
A74: End Closer Savvy ○ | B74: =SWITCH(Main!$E$15, "S-A", C74, "B-C", D74, "D-E-F", E74, "G", F74, "Not Found") -> 139 | C74: 191 | D74: 157 | E74: 139 | F74: 122 | G74: End
A75: Lucky Seven | B75: 174
B76: Green values in this column changes depending on your aptitude | C76: S-A | D76: B-C | E76: D-E-F | F76: G

Sheet Blue
A1: None | B1: 0
A2: Be Still | B2: =SWITCH(Main!D$15, "S-A", C2, "B-C", D2, "D-E-F", E2, "G", F2, "Not Found") -> 239 | C2: 239 | D2: 195 | E2: 174 | F2: 152 | G2: Late
A3: Familiar Ground | B3: 217 | G3: Dirt
A4: Free-Spirited | B4: =SWITCH(Main!E$13, "S-A", C4, "B-C", D4, "D-E-F", E4, "G", F4, "Not Found") -> 174 | C4: 239 | D4: 195 | E4: 174 | F4: 152 | G4: Long
A5: Ignited Spirit STA | B5: 263
A6: Corner Recovery ○ | B6: 217
A7: Straightaway Recovery | B7: 217
A8: Lay Low | B8: 217
A9: Pace Strategy | B9: 217
A10: Calm in a Crowd | B10: 217
A11: Stamina to Spare | B11: =SWITCH(Main!$C$15, "S-A", C11, "B-C", D11, "D-E-F", E11, "G", F11, "Not Found") -> 195 | C11: 239 | D11: 195 | E11: 174 | F11: 152 | G11: Pace
A12: Preferred Position | B12: =SWITCH(Main!$C$15, "S-A", C12, "B-C", D12, "D-E-F", E12, "G", F12, "Not Found") -> 195 | C12: 239 | D12: 195 | E12: 174 | F12: 152 | G12: Pace
A13: Standing By | B13: =SWITCH(Main!$E$15, "S-A", C13, "B-C", D13, "D-E-F", E13, "G", F13, "Not Found") -> 174 | C13: 239 | D13: 195 | E13: 174 | F13: 152 | G13: End
A14: Wait-and-See | B14: =SWITCH(Main!$B$13, "S-A", C14, "B-C", D14, "D-E-F", E14, "G", F14, "Not Found") -> 174 | C14: 239 | D14: 195 | E14: 174 | F14: 152 | G14: Sprint
A15: Watchful Eye | B15: =SWITCH(Main!$C$13, "S-A", C15, "B-C", D15, "D-E-F", E15, "G", F15, "Not Found") -> 195 | C15: 239 | D15: 195 | E15: 174 | F15: 152 | G15: Mile | H15: =SWITCH(Main!$E$13, "S-A", C18, "B-C", D18, "D-E-F", E18, "G", F18, "Not Found") -> 174
A16: Rosy Outlook | B16: =SWITCH(Main!$D$13, "S-A", C16, "B-C", D16, "D-E-F", E16, "G", F16, "Not Found") -> 239 | C16: 239 | D16: 195 | E16: 174 | F16: 152 | G16: Medium
A17: Deep Breaths | B17: =SWITCH(Main!$E$13, "S-A", C17, "B-C", D17, "D-E-F", E17, "G", F17, "Not Found") -> 174 | C17: 239 | D17: 195 | E17: 174 | F17: 152 | G17: Long
A18: Extra Tank | B18: =SWITCH(Main!$E$13, "S-A", C18, "B-C", D18, "D-E-F", E18, "G", F18, "Not Found") -> 174 | C18: 239 | D18: 195 | E18: 174 | F18: 152 | G18: Long
A19: Soft Step | B19: =SWITCH(Main!$D$13, "S-A", C19, "B-C", D19, "D-E-F", E19, "G", F19, "Not Found") -> 239 | C19: 239 | D19: 195 | E19: 174 | F19: 152 | G19: Medium
A20: Passing Pro | B20: =SWITCH(Main!$E$13, "S-A", C20, "B-C", D20, "D-E-F", E20, "G", F20, "Not Found") -> 174 | C20: 239 | D20: 195 | E20: 174 | F20: 152 | G20: Long
A21: Moxie | B21: =SWITCH(Main!$B$15, "S-A", C21, "B-C", D21, "D-E-F", E21, "G", F21, "Not Found") -> 152 | C21: 239 | D21: 195 | E21: 174 | F21: 152 | G21: Front
A22: Hydrate | B22: =SWITCH(Main!$C$15, "S-A", C22, "B-C", D22, "D-E-F", E22, "G", F22, "Not Found") -> 195 | C22: 239 | D22: 195 | E22: 174 | F22: 152 | G22: Pace
A23: A Small Breather | B23: =SWITCH(Main!$D$15, "S-A", C23, "B-C", D23, "D-E-F", E23, "G", F23, "Not Found") -> 239 | C23: 239 | D23: 195 | E23: 174 | F23: 152 | G23: Late
A24: After-School Stroll | B24: =SWITCH(Main!$E$15, "S-A", C24, "B-C", D24, "D-E-F", E24, "G", F24, "Not Found") -> 174 | C24: 239 | D24: 195 | E24: 174 | F24: 152 | G24: End
A25: Levelheaded | B25: =SWITCH(Main!$E$15, "S-A", C25, "B-C", D25, "D-E-F", E25, "G", F25, "Not Found") -> 174 | C25: 239 | D25: 195 | E25: 174 | F25: 152 | G25: End
A26: Triple 7s | B26: 217
A27: Shake It Out | B27: 217
B28: Green values in this column changes depending on your aptitude | C28: S-A | D28: B-C | E28: D-E-F | F28: G

Sheet Yellow
A1: None | B1: 0
A2: Ignited Spirit SPD | B2: 263
A3: Ignited Spirit PWR | B3: 263
A4: Ignited Spirit GUT | B4: 263
A5: Ignited Spirit WIT | B5: 263
A6: Corner Adept ○ | B6: 217
A7: Straightaway Adept | B7: 217
A8: Ramp Up | B8: 217
A9: Homestretch Haste | B9: 217
A10: Fast-Paced | B10: =SWITCH(Main!B$15, "S-A", C10, "B-C", D10, "D-E-F", E10, "G", F10, "Not Found") -> 152 | C10: 239 | D10: 195 | E10: 174 | F10: 152 | G10: Front
A11: Prepared to Pass | B11: =SWITCH(Main!C$15, "S-A", C11, "B-C", D11, "D-E-F", E11, "G", F11, "Not Found") -> 195 | C11: 239 | D11: 195 | E11: 174 | F11: 152 | G11: Pace
A12: Position Pilfer | B12: =SWITCH(Main!D$15, "S-A", C12, "B-C", D12, "D-E-F", E12, "G", F12, "Not Found") -> 239 | C12: 239 | D12: 195 | E12: 174 | F12: 152 | G12: Late
A13: Outer Swell | B13: =SWITCH(Main!D$15, "S-A", C13, "B-C", D13, "D-E-F", E13, "G", F13, "Not Found") -> 239 | C13: 239 | D13: 195 | E13: 174 | F13: 152 | G13: Late
A14: Masterful Gambit | B14: =SWITCH(Main!E$15, "S-A", C14, "B-C", D14, "D-E-F", E14, "G", F14, "Not Found") -> 174 | C14: 239 | D14: 195 | E14: 174 | F14: 152 | G14: End
A15: Gap Closer | B15: =SWITCH(Main!B$13, "S-A", C15, "B-C", D15, "D-E-F", E15, "G", F15, "Not Found") -> 174 | C15: 239 | D15: 195 | E15: 174 | F15: 152 | G15: Sprint
A16: Productive Plan | B16: =SWITCH(Main!C$13, "S-A", C16, "B-C", D16, "D-E-F", E16, "G", F16, "Not Found") -> 195 | C16: 239 | D16: 195 | E16: 174 | F16: 152 | G16: Mile
A17: Up-Tempo | B17: =SWITCH(Main!D$13, "S-A", C17, "B-C", D17, "D-E-F", E17, "G", F17, "Not Found") -> 239 | C17: 239 | D17: 195 | E17: 174 | F17: 152 | G17: Medium
A18: Steadfast | B18: =SWITCH(Main!D$13, "S-A", C18, "B-C", D18, "D-E-F", E18, "G", F18, "Not Found") -> 239 | C18: 239 | D18: 195 | E18: 174 | F18: 152 | G18: Medium
A19: Inside Scoop | B19: =SWITCH(Main!E$13, "S-A", C19, "B-C", D19, "D-E-F", E19, "G", F19, "Not Found") -> 174 | C19: 239 | D19: 195 | E19: 174 | F19: 152 | G19: Long
A20: Sprint Straightaways ◎ | B20: =SWITCH(Main!B$13, "S-A", C20, "B-C", D20, "D-E-F", E20, "G", F20, "Not Found") -> 210 | C20: 288 | D20: 236 | E20: 210 | F20: 183 | G20: Sprint
A21: Sprint Straightaways ○ | B21: =SWITCH(Main!B$13, "S-A", C21, "B-C", D21, "D-E-F", E21, "G", F21, "Not Found") -> 174 | C21: 239 | D21: 195 | E21: 174 | F21: 152 | G21: Sprint
A22: Sprint Corners ◎ | B22: =SWITCH(Main!B$13, "S-A", C22, "B-C", D22, "D-E-F", E22, "G", F22, "Not Found") -> 210 | C22: 288 | D22: 236 | E22: 210 | F22: 183 | G22: Sprint
A23: Sprint Corners ○ | B23: =SWITCH(Main!B$13, "S-A", C23, "B-C", D23, "D-E-F", E23, "G", F23, "Not Found") -> 174 | C23: 239 | D23: 195 | E23: 174 | F23: 152 | G23: Sprint
A24: Huge Lead | B24: =SWITCH(Main!B$13, "S-A", C24, "B-C", D24, "D-E-F", E24, "G", F24, "Not Found") -> 210 | C24: 288 | D24: 236 | E24: 210 | F24: 183 | G24: Sprint
A25: Mile Straightaways ◎ | B25: =SWITCH(Main!C$13, "S-A", C25, "B-C", D25, "D-E-F", E25, "G", F25, "Not Found") -> 236 | C25: 288 | D25: 236 | E25: 210 | F25: 183 | G25: Mile
A26: Mile Straightaways ○ | B26: =SWITCH(Main!C$13, "S-A", C26, "B-C", D26, "D-E-F", E26, "G", F26, "Not Found") -> 195 | C26: 239 | D26: 195 | E26: 174 | F26: 152 | G26: Mile
A27: Mile Corners ◎ | B27: =SWITCH(Main!C$13, "S-A", C27, "B-C", D27, "D-E-F", E27, "G", F27, "Not Found") -> 236 | C27: 288 | D27: 236 | E27: 210 | F27: 183 | G27: Mile
A28: Mile Corners ○ | B28: =SWITCH(Main!C$13, "S-A", C28, "B-C", D28, "D-E-F", E28, "G", F28, "Not Found") -> 195 | C28: 239 | D28: 195 | E28: 174 | F28: 152 | G28: Mile
A29: Shifting Gears | B29: =SWITCH(Main!C$13, "S-A", C29, "B-C", D29, "D-E-F", E29, "G", F29, "Not Found") -> 195 | C29: 239 | D29: 195 | E29: 174 | F29: 152 | G29: Mile
A30: Unyielding Spirit | B30: =SWITCH(Main!C$13, "S-A", C30, "B-C", D30, "D-E-F", E30, "G", F30, "Not Found") -> 195 | C30: 239 | D30: 195 | E30: 174 | F30: 152 | G30: Mile
A31: Medium Straightaways ◎ | B31: =SWITCH(Main!D$13, "S-A", C31, "B-C", D31, "D-E-F", E31, "G", F31, "Not Found") -> 288 | C31: 288 | D31: 236 | E31: 210 | F31: 183 | G31: Medium
A32: Medium Straightaways ○ | B32: =SWITCH(Main!D$13, "S-A", C32, "B-C", D32, "D-E-F", E32, "G", F32, "Not Found") -> 239 | C32: 239 | D32: 195 | E32: 174 | F32: 152 | G32: Medium
A33: Medium Corners ◎ | B33: =SWITCH(Main!D$13, "S-A", C33, "B-C", D33, "D-E-F", E33, "G", F33, "Not Found") -> 288 | C33: 288 | D33: 236 | E33: 210 | F33: 183 | G33: Medium
A34: Medium Corners ○ | B34: =SWITCH(Main!D$13, "S-A", C34, "B-C", D34, "D-E-F", E34, "G", F34, "Not Found") -> 239 | C34: 239 | D34: 195 | E34: 174 | F34: 152 | G34: Medium
A35: Long Straightaways ◎ | B35: =SWITCH(Main!E$13, "S-A", C35, "B-C", D35, "D-E-F", E35, "G", F35, "Not Found") -> 210 | C35: 288 | D35: 236 | E35: 210 | F35: 183 | G35: Long
A36: Long Straightaways ○ | B36: =SWITCH(Main!E$13, "S-A", C36, "B-C", D36, "D-E-F", E36, "G", F36, "Not Found") -> 174 | C36: 239 | D36: 195 | E36: 174 | F36: 152 | G36: Long
A37: Long Corners ◎ | B37: =SWITCH(Main!E$13, "S-A", C37, "B-C", D37, "D-E-F", E37, "G", F37, "Not Found") -> 210 | C37: 288 | D37: 236 | E37: 210 | F37: 183 | G37: Long
A38: Long Corners ○ | B38: =SWITCH(Main!E$13, "S-A", C38, "B-C", D38, "D-E-F", E38, "G", F38, "Not Found") -> 174 | C38: 239 | D38: 195 | E38: 174 | F38: 152 | G38: Long
A39: Keeping the Lead | B39: =SWITCH(Main!E$13, "S-A", C39, "B-C", D39, "D-E-F", E39, "G", F39, "Not Found") -> 174 | C39: 239 | D39: 195 | E39: 174 | F39: 152 | G39: Long
A40: Pressure | B40: =SWITCH(Main!E$13, "S-A", C40, "B-C", D40, "D-E-F", E40, "G", F40, "Not Found") -> 174 | C40: 239 | D40: 195 | E40: 174 | F40: 152 | G40: Long
...

Sheet Aptitudes
A1: Name | B1: Turf | C1: Dirt | D1: Sprint | E1: Mile | F1: Medium | G1: Long | H1: Front | I1: Pace | J1: Late | K1: End
A2: Agnes Tachyon | B2: S-A | C2: G | D2: G | E2: D-E-F | F2: S-A | G2: B-C | H2: D-E-F | I2: S-A | J2: B-C | K2: D-E-F
A3: Air Groove | B3: S-A | C3: G | D3: B-C | E3: B-C | F3: S-A | G3: D-E-F | H3: D-E-F | I3: S-A | J3: S-A | K3: G
A4: Biwa Hayahide | B4: S-A | C4: D-E-F | D4: D-E-F | E4: B-C | F4: S-A | G4: S-A | H4: D-E-F | I4: S-A | J4: B-C | K4: D-E-F
A5: Curren Chan | B5: S-A | C5: D-E-F | D5: S-A | E5: D-E-F | F5: G | G5: G | H5: B-C | I5: S-A | J5: D-E-F | K5: G
A6: Daiwa Scarlet | B6: S-A | C6: G | D6: D-E-F | E6: S-A | F6: S-A | G6: B-C | H6: S-A | I6: S-A | J6: D-E-F | K6: G
A7: Eishin Flash | B7: S-A | C7: G | D7: G | E7: D-E-F | F7: S-A | G7: S-A | H7: G | I7: B-C | J7: S-A | K7: B-C
A8: El Condor Pasa | B8: S-A | C8: B-C | D8: D-E-F | E8: S-A | F8: S-A | G8: B-C | H8: D-E-F | I8: S-A | J8: S-A | K8: B-C
A9: Fuji Kiseki | B9: S-A | C9: D-E-F | D9: B-C | E9: S-A | F9: B-C | G9: D-E-F | H9: B-C | I9: S-A | J9: B-C | K9: G
A10: Gold City | B10: S-A | C10: D-E-F | D10: D-E-F | E10: S-A | F10: B-C | G10: B-C | H10: D-E-F | I10: S-A | J10: S-A | K10: D-E-F
A11: Gold Ship | B11: S-A | C11: G | D11: G | E11: B-C | F11: S-A | G11: S-A | H11: G | I11: B-C | J11: B-C | K11: S-A
A12: Grass Wonder | B12: S-A | C12: G | D12: G | E12: S-A | F12: B-C | G12: S-A | H12: D-E-F | I12: S-A | J12: S-A | K12: D-E-F
... A44: Winning Ticket | B44: S-A | C44: G | D44: G | E44: D-E-F | F44: S-A | G44: B-C | H44: G | I44: B-C | J44: S-A | K44: G

Sheet Red
A1: None | B1: 0
A3: Hesitant Front Runners | B3: 217
A4: Hesitant Pace Chasers | B4: 217
A5: Hesitant Late Surgers | B5: 217
A6: Hesitant End Closers | B6: 217
A7: Intimidate | B7: =SWITCH(Main!$B$13, "S-A", C7, "B-C", D7, "D-E-F", E7, "G", F7, "Not Found") -> 210 | C7: 288 | D7: 236 | E7: 210 | F7: 183 | G7: Sprint
A8: Speed Eater | B8: =SWITCH(Main!$C$13, "S-A", C8, "B-C", D8, "D-E-F", E8, "G", F8, "Not Found") -> 195 | C8: 239 | D8: 195 | E8: 174 | F8: 152 | G8: Mile
A9: Tether | B9: =SWITCH(Main!$D$13, "S-A", C9, "B-C", D9, "D-E-F", E9, "G", F9, "Not Found") -> 239 | C9: 239 | D9: 195 | E9: 174 | F9: 152 | G9: Medium
A10: Intense Gaze | B10: =SWITCH(Main!$E$15, "S-A", C10, "B-C", D10, "D-E-F", E10, "G", F10, "Not Found") -> 174 | C10: 239 | D10: 195 | E10: 174 | F10: 152 | G10: End
A11: Opening Gambit | B11: =SWITCH(Main!$C$13, "S-A", C11, "B-C", D11, "D-E-F", E11, "G", F11, "Not Found") -> 195 | C11: 239 | D11: 195 | E11: 174 | F11: 152 | G11: Mile
A12: Restart | B12: =SWITCH(Main!$B$15, "S-A", C12, "B-C", D12, "D-E-F", E12, "G", F12, "Not Found") -> 152 | C12: 239 | D12: 195 | E12: 174 | F12: 152 | G12: Front
A13: Frenzied Front Runners | B13: 174
A14: Frenzied Pace Chasers | B14: 174
A15: Frenzied Late Surgers | B15: 174
A16: Frenzied End Closers | B16: 174
A17: Trick (Front) | B17: 217
A18: Trick (Rear) | B18: 217
A19: Subdued Front Runners | B19: 217
A20: Flustered Front Runners | B20: 217
A21: Subdued Pace Chasers | B21: 217
A22: Flustered Pace Chasers | B22: 217
A23: Subdued Late Surgers | B23: 217
A24: Flustered Late Surgers | B24: 217
... A26: Flustered End Closers | B26: 217
A27: Stop Right There! | B27: =SWITCH(Main!$B$13, "S-A", C27, "B-C", D27, "D-E-F", E27, "G", F27, "Not Found") -> 210 | C27: 288 | D27: 236 | E27: 210 | F27: 183 | G27: Sprint
A28: Murmur | B28: =SWITCH(Main!$D$13, "S-A", C28, "B-C", D28, "D-E-F", E28, "G", F28, "Not Found") -> 239 | C28: 239 | D28: 195 | E28: 174 | F28: 152 | G28: Medium
A29: Stamina Eater | B29: =SWITCH(Main!$E$13, "S-A", C29, "B-C", D29, "D-E-F", E29, "G", F29, "Not Found") -> 174 | C29: 239 | D29: 195 | E29: 174 | F29: 152 | G29: Long
A30: Sharp Gaze | B30: =SWITCH(Main!$D$15, "S-A", C30, "B-C", D30, "D-E-F", E30, "G", F30, "Not Found") -> 239 | C30: 239 | D30: 195 | E30: 174 | F30: 152 | G30: Late
A31: Smoke Screen | B31: =SWITCH(Main!$E$13, "S-A", C31, "B-C", D31, "D-E-F", E31, "G", F31, "Not Found") -> 103 | C31: 142 | D31: 116 | E31: 103 | F31: 90 | G31: Long
A32: Disorient | B32: =SWITCH(Main!$C$15, "S-A", C32, "B-C", D32, "D-E-F", E32, "G", F32, "Not Found") -> 77 | C32: 94 | D32: 77 | E32: 68 | F32: 60 | G32: Pace
B33: Green values in this column changes depending on your aptitude | C33: S-A | D33: B-C | E33: D-E-F | F33: G

Sheet Purple
A1: None | B1: 0
A2: Right-Handed × | B2: -129 | D2: If you get a debuff/purple skill that is not listed here, please contact me with a screenshot of your Uma's rating, skill list and stats
A3: Left-Handed × | B3: -129
A4: Spring Runner × | B4: -129
A5: Summer Runner × | B5: -129
A6: Fall Runner × | B6: -129
A7: Winter Runner × | B7: -129
A8: Outer Post Averseness | B8: -129
A9: Inner Post Averseness | B9: -129
A10: G1 Averseness | B10: -129
A11: Tokyo Racecourse × | B11: -129
A12: Nakayama Racecourse × | B12: -129
A13: Hanshin Racecourse × | B13: -129
A14: Kyoto Racecourse × | B14: -129
... A33: Gatekept | B33: -174

Sheet Inherited Unique Skill
A1: None | B1: 0
A2: U=ma2 | B2: 180 | C2: Agnes Tachyon | E2: Unique skills are worth 180 points currently. In the future we can expect a few of them to give 198 pts
A3: Pure Heart | B3: 180 | C3: Super Creek | E3: Loves Only You
A4: Super-Duper Climax | B4: 180 | C4: Haru Urara | E4: Admire Vega (Christmas)
A5: Certain Victory | B5: 180 | C5: Tokai Teio (Anime) | E5: Chronogenesis
A6: Legacy of the Strong | B6: 180 | C6: Mejiro McQueen (Anime) | E6: Cesario (Wedding)
A7: Shooting Star | B7: 180 | C7: Special Week | E7: Mejiro Ramonu (Wedding)
A8: The View from the Lead Is Mine! | B8: 180 | C8: Silence Suzuka | E8: Orfevre
A9: Sky-High Teio Step | B9: 180 | C9: Tokai Teio
A10: Triumphant Pulse | B10: 180 | C10: Oguri Cap
A11: Anchors Aweigh! | B11: 180 | C11: Gold Ship
A12: Cut and Drive! | B12: 180 | C12: Vodka
A13: Resplendent Red Ace | B13: 180 | C13: Daiwa Scarlet
A14: Where There's a Will, There's a Way | B14: 180 | C14: Grass Wonder
A15: The Duty of Dignity Calls | B15: 180 | C15: Mejiro McQueen
A16: Victoria por plancha ☆ | B16: 180 | C16: El Condor Pasa
A17: This Dance Is for Vittoria! | B17: 180 | C17: T.M. Opera O
A18: Behold Thine Emperor's Divine Might | B18: 180 | C18: Symboli Rudolf
A19: Blazing Pride | B19: 180 | C19: Air Groove
A20: ∴win Q.E.D. | B20: 180 | C20: Biwa Hayahide
... A58: Moving Past, and Beyond | B58: 180 | C58: Mejiro Dober

Sheet changelog
A1: Date | B1: Version | C1: Log | E1: Latest Version | F1: =IFERROR(__xludf.DUMMYFUNCTION("INDEX(FILTER(changelog!B:B , changelog!B:B<>""""), COUNTA(FILTER(changelog!B:B,changelog!B:B<>"""")))"),"2.2.5") -> 2.2.5 | J1: Maintainer | M1: Contributors
A2: 45865 | B2: 1.1.1 | C2: Improved Validation Sheet | J2: dak | N2: Neon | P2: IceDynamix
A3: 45866 | B3: 1.1.2 | C3: Thank you to @zonseki for the suggestion Added Lvl 6 skills ============================================================ Separated 1*/2* versions of Unique skills along with unreleased Umas Fixed some values for Gold skills fucked up and fixed up coloring when selecting Gold skills | E3: Logs in Green represent changes to the calculator | F3: Logs in Red represent issues with the calculator | G3: very funny guys
A4: 45867 | B4: 1.1.3 | C4: just added more info and tidied up some sheets | E4: Please don't request access to this file and make a copy, thanks | N4: Data Entry | P4: Formula
A5: 45868 | B5: 1.2.0 | C5: Added formula for calculating the score of a stat directly instead of using the VLOOKUP formula to manually look up the score on a separate sheet. Big thanks to IceDynamix (@icedynamix) for helping out with writing up the formula
J6: Acknowledgments
J8: @zonseki
A9: 45871 | B9: 1.2.1 | C9: Deleted "values" sheet as it serves no purpose anymore | D9: You may find the hidden sheets here | J9: u/TalesOfTea
A10: 45872 | B10: 1.2.2 | C10: Added Narita Taishin Unique skill in preparation to her debut banner | J10: u/Arastas
A11: 45873 | B11: 1.2.3 | C11: Added Purple skills lmao | J11: u/AugmentedWhiteWind
A12: 45874 | B12: 1.2.4 | C12: Thank you to u/TalesOfTea for the suggestion Cleaned up the Sheet by hiding skill scores sheets. Also protected those sheets to give a warning to the user to not tamper, you can always make another copy so do whatever you want | J12: u/Artistic-Monitor-211
J13: u/seth-rah
J14: @biltex
J15: u/howdoescasual
A16: 45880 | B16: 1.2.5 | C16: Added Smart Falcon Unique skill to skill list | J16: @manmanpower15
A17: 45885 | B17: 1.2.6 | C17: Thank you to u/Arastas for pointing this out Added Straightaway Acceleration skill to Yellow skills list after missing it completely | J17: @kana_dmk
J18: @henrikxlvi
J19: u/AceKittyhawk
A20: 45887 | B20: 1.3.0 | C20: Thank you to u/AugmentedWhitewind for the great suggestion QoL: Added a Reset button to clear the skill selection table. This makes use of a script, please read There’s a Script in my calculator!!. Emphasizing the fact that it's SAFE and Google is just scaring you. You can paste the code through ChatGPT if you're suspicious or whatever If you want a scriptless version: Scriptless copy of Rating calculator | D20: 2nd half of this log from this date is slightly irrelevant as a reddit user found a fix to prevent the script from asking access permission to all of the user's spreadsheets | J20: u/BlizzardVenom
A25: 45889 | B25: 1.3.1 | C25: Added Narita Brian Unique skill
A26: 45893 | B26: 1.3.2 | C26: A lot of people have trouble using the calc so I made a makeshift "How to use" Sheet along with the maths. Improvements to the formatting will be made later | E26: so busy today e.e
A28: 45893 | B28: 1.4.0 | C28: Added a "Delete all skills" checkbox so that mobile users can clear skills too. Just as a warning, there will be no popup asking for confirmation to delete skills wether you are on Mobile or not
A31: 45894 | B31: 1.4.1 | C31: Thank you to u/seth-rah for the suggestion Updated the script file so that it's prevented from asking for access to all of the user's google spreadsheets.
A34: 45897 | B34: 1.5.0 | C34: Added Maths and Formulas sheet Added Mayano Top Gun (Wedding) + Air Groove (Wedding) Unique skills
A36: 45898 | C36: There seems to be an issue with Straightaway Spurt, the scoring is incorrect. I'm trying to figure out what the issue is here. For now I set its score to 217 as a "fix" for S-A/B-C End aptitude umas, I can't tell if that would fix it for D-E-F and G Thank you to @biltex and u/howdoescasual for the initial reports
C40: There might be an issue with another skill, will check later which one is causing a similar issue. I apologize if I have ruined a few Open League Ace runs
A42: Spe 1 2025 | B42: 1.6.0 | C42: QoL: Using the reset button/checkbox should set everything to a blank cell instead of "None", this facilitates in typing the skill name for quicker access instead of having to manually remove "None". + Deleted "None" Sheet as it is now irrelevant ============================================================ QoL 2: Additionally have added Aptitude Templates, by selecting an Uma from the dropdown, the sheet will automatically fill in the right Aptitudes. Please keep in mind that you have to manually change any Aptitudes that has been affected by your uma's Heritage
C49: Not tested on mobile ^
B50: 1.6.1 | C50: I believe that "Extra Tank" and "Straightaway Spurt" were the skills with incorrect scores, set both of them a fixed score of 217. I have yet to know how it affects their Gold skill counterparts but for now I'll keep an eye on user reports.
A54: Spe 3 2025 | B54: 1.6.2 | C54: Exactly as I feared, Encroaching Shadow (Gold skill of S. Spurt) has an incorrect scoring by 51 points. It is only available for Narita Taishin for now, so knowing if the score is the same for different End Closer aptitudes isn't possible yet, but assuming it is sounds plausible as it was the case for Spurt and Tank. This is likely to cause the same issue for Adrenaline Rush (Gold skill of E.Tank).
C58: Set scores of Encroaching Shadow and Adrenaline Rush to 508 fixed
A59: Spe 7 2025 | B59: 1.6.3 | C59: Added Seiun Sky
A60: Spe 17 2025 | B60: 1.6.4 | C60: Added Hishi Amazon
A61: Spe 22 2025 | B61: 1.6.5 | C61: Added Grass Wonder & El Condor Pasa (Fantasy)
A62: 45931 | B62: 1.6.6 | C62: Added Fuji Kiseki
A63: 45935 | B63: 1.6.7 | C63: Added Gold City
A64: 45943 | B64: 1.6.8 | C64: Added Special Week & Maruzensky (Summer)
A65: 45949 | B65: 1.6.9 | C65: Added Meisho Doto :3
A66: 45950 | B66: 1.7.0 | C66: Added version checking, so that users can verify they are on the latest version of the spreadsheet. Please make sure that in File > Settings > Calculation > Recalculation is set to every minute for this work in real time. If set to anything else, it will update every 30 mins (by default) or every hour if set by the user.
C71: Removed "Last Updated" Part in the README sheet as it has no use anymore
...
